<?xml version="1.0"?>
<robot name="New Bot" xmlns:xacro="http://www.ros.org/wiki/xacro">

<!-- Bring in simulation data for Gazebo. -->
<xacro:include filename="$(find newbot_description)/urdf/newbot.gazebo" />
<xacro:include filename="$(find newbot_description)/urdf/materials.xacro" />


<!-- Properties -->
<xacro:property name="PI" value="3.1415926535897931" />


<!-- change the inertia for the URDF when finished-->


<link name="base_link"></link>


<!-- chasis -->

<link name="chassis_link">

	<visual>
	 <origin xyz="0 0 0"/>
	 <geometry>
     <box size="1.8 0.755 0.2" />
	 </geometry>
	 <material name="body" />
	</visual>

	<collision>
	 <origin xyz="0 0 0"/>
	 <geometry>
	   <box size="1.8 0.755 0.2" />
	 </geometry>
	</collision>

	<inertial>
	 <origin xyz="0.0422171696051465 0.00189728780308063 -0.0378333807867307" rpy="0 0 0"/>
	 <mass value="16.523"/>
	 <inertia
	  ixx="0.3136" ixy="-0.0008" ixz="0.0164"
	  iyy="0.3922" iyz="-0.0009"
	  izz="0.4485"/>
	</inertial>

</link>

<joint name="chasis_link_joint" type="fixed">
	<origin xyz="0 0 0.375" rpy="0 0 0" />
	<parent link="base_link"/>
	<child link="chassis_link" />
</joint>



<!--wheel-->

<xacro:macro name="wheel" params="prefix *joint_pose">


<link name="${prefix}_wheel_link">
      <visual>
        <origin xyz="0 0 0" rpy="${PI/2} 0 0"/>
        <geometry>
          <cylinder length="0.26" radius="0.24"/>
        </geometry>
        <material name="wheels" />
      </visual>


      <collision>
        <origin xyz="0 0 0" rpy="${PI/2} 0 0"/>
        <geometry>
          <cylinder length="0.26" radius="0.24"/>
        </geometry>
      </collision>


      <inertial>
        <origin xyz="9.1812e-6 1.0274e-6 -4.4809e-6" rpy="0 0 0"/>
        <mass value="0.477"/>
        <inertia
          ixx="0.0013" ixy="0" ixz="0"
          iyy="0.0024" iyz="0"
          izz="0.0013"/>
      </inertial>

</link>


	<gazebo reference="${prefix}_wheel_link">
  	  <mu1>0.2</mu1>
 	   <mu2>0.2</mu2>
     	 <material>Gazebo/DarkGrey</material>
	</gazebo>


	<joint name="${prefix}_wheel" type="continuous">
    	  <parent link="base_link"/>
    	  <child link="${prefix}_wheel_link" />
    	  <xacro:insert_block name="joint_pose" />
   	   <axis xyz="0 1 0" />
	</joint>



    <!-- It's more straightforward for Gazebo to simulate as if there's an actuator per wheel. -->

	<transmission name="${prefix}_wheel_trans">
    	  <type>transmission_interface/SimpleTransmission</type>
   	   <joint name="${prefix}_wheel">
   	     <hardwareInterface>EffortJointInterface</hardwareInterface>
   	   </joint>
   	   <actuator name="${prefix}_actuator">
		<hardwareInterface>EffortJointInterface</hardwareInterface>
   	     <mechanicalReduction>1</mechanicalReduction>
   	   </actuator>
   	</transmission>

</xacro:macro>


  <xacro:wheel prefix="front_left">
    <origin xyz="0.70465 0.51502 0.23923" rpy="0 0 0" />
  </xacro:wheel>
  <xacro:wheel prefix="front_right">
    <origin xyz="0.70465 -0.51501 0.23923" rpy="0 0 0" />
  </xacro:wheel>
  <xacro:wheel prefix="rear_left">
    <origin xyz="-0.70542 0.51502 0.23923" rpy="0 0 0" />
  </xacro:wheel>
  <xacro:wheel prefix="rear_right">
    <origin xyz="-0.70542 -0.51501 0.23923" rpy="0 0 0" />
  </xacro:wheel>

<!-- end of wheel description -->>


<!-- laser base -->
 
  <joint name="camera_joint" type="fixed">
    <origin xyz="-0.091106 0.0056361 0.49357" rpy="0 0 0"/>
    <parent link="base_link"/>
    <child link="camera_link"/>
  </joint>


  <link name="camera_link">
    <collision>
	<!-- re edit the position in collision to not collide with the chasis in origin z location-->
      <origin xyz="0 0 0.04" rpy="0 0 0"/>
      <geometry>
	      <box size="0.5 0.25 0.1" />
      </geometry>
    </collision>

    <visual>

      <origin xyz="0 0 0" rpy="0 0 0"/>
      <geometry>
        <box size="0.5 0.25 0.1" />
      </geometry>
      <material name="top"/>
    </visual>

    <inertial>
      <mass value="1e-5" />
      <origin xyz="-7.2868e-8 -3.9636e-6 0.013631" rpy="0 0 0"/>
      <inertia ixx="1e-6" ixy="0" ixz="0" iyy="1e-6" iyz="0" izz="1e-6" />
    </inertial>
  </link>



<!-- Hokuyo Laser --> 

 <joint name="hokuyo_joint" type="fixed">
    <origin xyz="0 0 0.12" rpy="0 0 0"/>
    <parent link="camera_link"/>
    <child link="laser_link"/>
  </joint>

  <link name="laser_link">
    <collision>
      <origin xyz="0 0 0.05" rpy="0 0 0"/>
      <geometry>
	<box size="0.5 0.25 0.047" />
      </geometry>
    </collision>

    <visual>
      <origin xyz="0 0 0" rpy="0 0 0"/>
      <geometry>
  <box size="0.5 0.25 0.047" />
      </geometry>
	<material name="top"/>
    </visual>

    <inertial>
      <mass value="1e-5" />
      <origin xyz="-5.7094e-7 -8.9157e-6 0.1" rpy="0 0 0"/>
      <inertia ixx="1e-6" ixy="0" ixz="0" iyy="1e-6" iyz="0" izz="1e-6" />
    </inertial>
  </link>

</robot>
